2018-11-19 15:47:26,064  aggregator data_store::inner()  INFO  (PID: 10484)>  Connecting to db
2018-11-19 15:47:26,111  aggregator data_store::inner()  INFO  (PID: 10484)>  Closing connection
2018-11-19 15:49:15,463  aggregator t::<module>()  INFO  (PID: 18844)>  Starting database transactions
2018-11-19 15:49:15,463  aggregator data_store::inner()  INFO  (PID: 18844)>  Connecting to db
2018-11-19 15:49:15,479  aggregator data_store::select_data()  INFO  (PID: 18844)>  following items retrieved [('1', 'navi', 'kannan', 'nav@gmail.com', '1111'), ('2', 'navi', 'kannan', 'nav@gmail.com', '1111'), ('3', 'navi', 'kannan', 'nav@gmail.com', '1111'), ('3', 'navi', 'kannan', 'nav@gmail.com', '1111'), ('3', 'navi', 'kannan', 'nav@gmail.com', '1111'), ('3', 'navi', 'kannan', 'nav@gmail.com', '1111'), ('3', 'navi', 'kannan', 'nav@gmail.com', '1111'), ('3', 'navi', 'kannan', 'nav@gmail.com', '1111'), ('3', 'navi', 'kannan', 'nav@gmail.com', '1111'), ('3', 'navi', 'kannan', 'nav@gmail.com', '1111'), ('3', 'navi', 'kannan', 'nav@gmail.com', '1111')]
2018-11-19 15:49:15,511  aggregator data_store::inner()  INFO  (PID: 18844)>  Closing connection
2018-11-19 15:50:06,681  aggregator t::<module>()  INFO  (PID: 23316)>  Starting database transactions
2018-11-19 15:50:06,696  aggregator data_store::inner()  INFO  (PID: 23316)>  Connecting to db
2018-11-19 15:50:06,696  aggregator data_store::select_data()  INFO  (PID: 23316)>  following items retrieved [('1', 'navi', 'kannan', 'nav@gmail.com', '1111'), ('2', 'navi', 'kannan', 'nav@gmail.com', '1111'), ('3', 'navi', 'kannan', 'nav@gmail.com', '1111'), ('3', 'navi', 'kannan', 'nav@gmail.com', '1111'), ('3', 'navi', 'kannan', 'nav@gmail.com', '1111'), ('3', 'navi', 'kannan', 'nav@gmail.com', '1111'), ('3', 'navi', 'kannan', 'nav@gmail.com', '1111'), ('3', 'navi', 'kannan', 'nav@gmail.com', '1111'), ('3', 'navi', 'kannan', 'nav@gmail.com', '1111'), ('3', 'navi', 'kannan', 'nav@gmail.com', '1111'), ('3', 'navi', 'kannan', 'nav@gmail.com', '1111')]
2018-11-19 15:50:06,712  aggregator data_store::inner()  INFO  (PID: 23316)>  Closing connection
2018-11-19 15:50:24,031  aggregator t::<module>()  INFO  (PID: 22576)>  Starting database transactions
2018-11-19 15:50:24,046  aggregator data_store::inner()  INFO  (PID: 22576)>  Connecting to db
2018-11-19 15:50:24,062  aggregator data_store::select_data()  ERROR  (PID: 22576)>  Select failed :select * from contacts where first_name=:1-('navi',) due to no such table: contacts
Traceback (most recent call last):
  File "C:\Users\navkanna\PycharmProjects\FirmsDemo\Aggregator\Aggregator\utils\data_store.py", line 81, in select_data
    self.cur.execute(query, bind)
sqlite3.OperationalError: no such table: contacts
2018-11-19 15:50:24,077  aggregator data_store::inner()  INFO  (PID: 22576)>  Closing connection
2018-11-19 15:51:31,697  aggregator t::<module>()  INFO  (PID: 6248)>  Starting database transactions
2018-11-19 15:51:31,697  aggregator data_store::inner()  INFO  (PID: 6248)>  Connecting to db
2018-11-19 15:51:31,728  aggregator data_store::select_data()  ERROR  (PID: 6248)>  Select failed :select * from contacts where first_name=:1-('navi',) due to no such table: contacts
Traceback (most recent call last):
  File "C:\Users\navkanna\PycharmProjects\FirmsDemo\Aggregator\Aggregator\utils\data_store.py", line 82, in select_data
    self.cur.execute(query, bind)
sqlite3.OperationalError: no such table: contacts
2018-11-19 15:51:31,759  aggregator data_store::inner()  INFO  (PID: 6248)>  Closing connection
2018-11-19 15:52:06,262  aggregator t::<module>()  INFO  (PID: 5144)>  Starting database transactions
2018-11-19 15:52:06,277  aggregator data_store::inner()  INFO  (PID: 5144)>  Connecting to db
2018-11-19 15:52:06,293  aggregator data_store::select_data()  INFO  (PID: 5144)>  following items retrieved []
2018-11-19 15:52:06,309  aggregator data_store::inner()  INFO  (PID: 5144)>  Closing connection
2018-11-19 15:54:57,780  aggregator t::<module>()  INFO  (PID: 12888)>  Starting database transactions
2018-11-19 15:54:57,796  aggregator data_store::inner()  INFO  (PID: 12888)>  Connecting to db
2018-11-19 15:54:57,811  aggregator data_store::select_data()  INFO  (PID: 12888)>  following items retrieved []
2018-11-19 15:54:57,827  aggregator data_store::select_data()  ERROR  (PID: 12888)>  Select failed :select * from contacts where first_name=:1-('nav',) due to ('select * from contacts where first_name=:1', ('nav',), [])
Traceback (most recent call last):
  File "C:\Users\navkanna\PycharmProjects\FirmsDemo\Aggregator\Aggregator\utils\data_store.py", line 89, in select_data
    raise NoDataAvailableException(query,bind,data)
utils.data_store.NoDataAvailableException: ('select * from contacts where first_name=:1', ('nav',), [])
2018-11-19 15:54:57,827  aggregator data_store::inner()  INFO  (PID: 12888)>  Closing connection
2018-11-19 16:01:53,188  aggregator t::<module>()  INFO  (PID: 14868)>  Starting database transactions
2018-11-19 16:01:53,197  aggregator data_store::inner()  INFO  (PID: 14868)>  Connecting to db
2018-11-19 16:01:53,213  aggregator data_store::select_data()  ERROR  (PID: 14868)>  Select failed :select * from contacts where first_name=:1-('nav',) due to no such table: contacts
Traceback (most recent call last):
  File "C:\Users\navkanna\PycharmProjects\FirmsDemo\Aggregator\Aggregator\utils\data_store.py", line 92, in select_data
    self.cur.execute(query, bind)
sqlite3.OperationalError: no such table: contacts
2018-11-19 16:01:53,228  aggregator data_store::inner()  INFO  (PID: 14868)>  Closing connection
2018-11-19 16:02:42,301  aggregator t::<module>()  INFO  (PID: 23100)>  Starting database transactions
2018-11-19 16:02:42,316  aggregator data_store::inner()  INFO  (PID: 23100)>  Connecting to db
2018-11-19 16:02:42,332  aggregator data_store::inner()  ERROR  (PID: 23100)>  unable to open database file
Traceback (most recent call last):
  File "C:\Users\navkanna\PycharmProjects\FirmsDemo\Aggregator\Aggregator\utils\data_store.py", line 26, in inner
    ret=f(*args, **kwargs)
  File "C:\Users\navkanna\PycharmProjects\FirmsDemo\Aggregator\Aggregator\utils\data_store.py", line 58, in connect
    self.conn = sqlite3.connect(self.db)
sqlite3.OperationalError: unable to open database file
2018-11-19 16:02:42,332  aggregator data_store::select_data()  ERROR  (PID: 23100)>  Select failed :select * from contacts where first_name=:1-('nav',) due to 'NoneType' object has no attribute 'execute'
Traceback (most recent call last):
  File "C:\Users\navkanna\PycharmProjects\FirmsDemo\Aggregator\Aggregator\utils\data_store.py", line 92, in select_data
    self.cur.execute(query, bind)
AttributeError: 'NoneType' object has no attribute 'execute'
2018-11-19 16:02:42,348  aggregator data_store::inner()  INFO  (PID: 23100)>  Closing connection
2018-11-19 16:02:42,363  aggregator data_store::inner()  ERROR  (PID: 23100)>  'NoneType' object has no attribute 'close'
Traceback (most recent call last):
  File "C:\Users\navkanna\PycharmProjects\FirmsDemo\Aggregator\Aggregator\utils\data_store.py", line 26, in inner
    ret=f(*args, **kwargs)
  File "C:\Users\navkanna\PycharmProjects\FirmsDemo\Aggregator\Aggregator\utils\data_store.py", line 113, in close
    self.conn.close ()
AttributeError: 'NoneType' object has no attribute 'close'
2018-11-19 16:06:13,333  aggregator t::<module>()  INFO  (PID: 20380)>  Starting database transactions
2018-11-19 16:06:13,349  aggregator data_store::inner()  INFO  (PID: 20380)>  Connecting to db
2018-11-19 16:06:13,366  aggregator data_store::select_data()  INFO  (PID: 20380)>  following items retrieved []
2018-11-19 16:06:13,378  aggregator data_store::select_data()  ERROR  (PID: 20380)>  Select failed :select * from contacts where first_name=:1-('nav',) due to ('select * from contacts where first_name=:1', ('nav',), [])
Traceback (most recent call last):
  File "C:\Users\navkanna\PycharmProjects\FirmsDemo\Aggregator\Aggregator\utils\data_store.py", line 96, in select_data
    raise NoDataAvailableException(query,bind,data)
utils.data_store.NoDataAvailableException: ('select * from contacts where first_name=:1', ('nav',), [])
2018-11-19 16:06:13,390  aggregator data_store::inner()  INFO  (PID: 20380)>  Closing connection
